#VRML_SIM R2019b utf8
WorldInfo {
  info [
    "Aldebaran's Nao H25 V5.0"
    "NAO is a programmable, 57-cm tall humanoid robot."
    "The body has 25 degrees of freedom (DOF)."
    "The sensors include 2 cameras, 4 microphones, sonar rangefinder, 2 IR emitters and receivers, 1 inertial board, and 8 pressure sensors."
  ]
  title "Aldebaran's Nao"
  basicTimeStep 4
  FPS 20
  contactProperties [
    ContactProperties {
      material1 "NAO foot material"
      coulombFriction [
        7
      ]
      bounce 0.3
      bounceVelocity 0.003
    }
  ]
}
Viewpoint {
  orientation -0.11786550646874941 0.9829824970731388 0.1409011456047177 1.6814862693353854
  position 2.762336704883043 1.0634244988922459 10.384280972130025
  follow "NAO"
}
TexturedBackground {
}
TexturedBackgroundLight {
}
DEF Nao Nao {
  hidden position_0_0 -9.75460646801269e-08
  hidden position2_0_0 -8.20005152926068e-09
  hidden position_0_1 2.9664660223503344e-07
  hidden position_0_2 4.6085085634159815e-07
  hidden rotation_12 -4.08561536872139e-09 -0.08376791789846035 -0.9964852913771266 9.884312124119402e-08
  hidden rotation_19 0 0.7071067811865475 0.7071067811865475 2.965293637235823e-07
  hidden position_19_0 1.6002797967449457e-06
  hidden rotation_20 1 0 0 1.6001932333301494e-06
  hidden position_20_0 2.962557215451796e-07
  hidden rotation_21 0 1 0 2.965293637235823e-07
  hidden position_21_0 2.0135320797415615e-07
  hidden rotation_22 0 1 0 2.0212918469683143e-07
  hidden position_22_0 1.8009110694317067e-07
  hidden rotation_23 0 1 0 1.812804499357409e-07
  hidden position_23_0 5.173917879510943e-07
  hidden rotation_24 1 0 0 5.170509687929607e-07
  hidden translation_25 0.01999995179237609 -0.0069990462037097245 -0.04099774584145796
  hidden rotation_25 3.732786895861927e-08 -3.754981109408058e-08 0.9999999999999987 -3.1415853298870746
  hidden rotation_29 0 0.7071067811865475 -0.7071067811865475 4.607327232879502e-07
  hidden position_29_0 2.4331173166974823e-06
  hidden rotation_30 1 0 0 2.43304524563397e-06
  hidden position_30_0 4.60323772442301e-07
  hidden rotation_31 0 1 0 4.607327232879502e-07
  hidden position_31_0 3.2345581314928036e-07
  hidden rotation_32 0 1 0 3.2373608622551644e-07
  hidden position_32_0 -1.8323911543660643e-07
  hidden rotation_33 0 -1 0 1.8371385344770487e-07
  hidden position_33_0 9.298523526784797e-07
  hidden rotation_34 1 0 0 9.296222901631809e-07
  hidden translation_35 0.02000004994617712 0.0070013861451947434 -0.040994352977224285
  hidden rotation_35 4.376126613493813e-08 -4.258029734389575e-08 0.9999999999999981 -3.141585306864774
  translation -0.0108445 0.333771 10.6932
  rotation 0.9999998116914846 0.000586450924966681 0.0001808101433607977 -1.5717891830568236
  controller "<extern>"
  supervisor TRUE
  bodySlot [
    DEF RobotHead Connector {
      translation -0.005 0.073 -0.0175
      rotation 0.9999999999999999 0 0 0
      name "robot_head_connector"
      model "boom_head"
      rotationStep 0.261799
      isLocked TRUE
      autoLock TRUE
      distanceTolerance 0.1
      axisTolerance 0.5
      rotationTolerance 0.5
    }
  ]
}
DEF BoomBase Robot {
  translation 0 0.05 -9.38
  children [
    DEF BoomBase Group {
      children [
        DEF BoomBaseJoint Transform {
          translation 0 0.25 0
          children [
            DEF BoomBaseJoint BallJoint {
              device [
                PositionSensor {
                }
              ]
              device2 [
                PositionSensor {
                }
              ]
              device3 [
                PositionSensor {
                }
              ]
              endPoint DEF BoomBody Solid {
                translation -0.007973831163473903 0.007009050341234446 10.000000355698617
                rotation 0.935114873282295 -0.2510429016008105 -0.25007525931623686 1.637044703282703
                children [
                  DEF BoomBody Group {
                    children [
                      DEF BoomBody Connector {
                        translation 0 10 0
                        rotation 0 1 0 0.523799
                        name "boom_body_connector"
                        model "boom_head"
                        isLocked TRUE
                        autoLock TRUE
                        distanceTolerance 0.1
                        axisTolerance 0.5
                        rotationTolerance 0.5
                      }
                      DEF BoomBody Shape {
                        appearance PBRAppearance {
                        }
                        geometry Cylinder {
                          height 20
                          radius 0.01
                        }
                      }
                    ]
                  }
                ]
                name "boom_body_solid"
                boundingObject USE BoomBody
                physics Physics {
                  density 0.1
                }
              }
            }
            DEF BoomBaseJoint Shape {
              appearance PBRAppearance {
              }
              geometry DEF BoomBaseJoint Sphere {
                radius 0.1
              }
            }
          ]
        }
        DEF BoomBase Shape {
          appearance PBRAppearance {
          }
          geometry Cylinder {
            height 0.5
            radius 0.1
          }
        }
      ]
    }
  ]
  name "boom_base_solid"
  supervisor TRUE
}
Floor {
  size 100 100
  appearance Appearance {
    texture ImageTexture {
      url [
        "textures/sand.jpg"
      ]
    }
  }
}
