#VRML_SIM R2019b utf8
WorldInfo {
  info [
    "Example world for demonstrating the InertialUnit."
  ]
  title "Leg Robot"
  basicTimeStep 16
}
Viewpoint {
  orientation 0.861164460007715 -0.5005436433984883 -0.08861057427298179 6.0572948483678095
  position -0.09408514371356883 0.14755568147058307 0.9140133636180935
}
TexturedBackground {
}
TexturedBackgroundLight {
}
CircleArena {
}
DEF Leg Robot {
  translation 1.5156117665997787e-05 0.00016436949588907908 3.0954125910975768e-09
  rotation -0.005042100277385393 -0.03696413706143527 0.9993038726013705 -1.359240684835847e-07
  children [
    DEF FOOT TouchSensor {
      translation 5.0931492636910544e-05 -0.00026266568908350394 -1.7465503162193236e-08
      rotation 2.1301022862901013e-06 -1.6159850374695507e-07 0.9999999999977183 4.5586234673045776e-07
      children [
        DEF ANKLE TouchSensor {
          translation -0.025101600454593167 0.020098107520769345 1.2336245869152366e-08
          rotation 0.9999995134395057 -0.0006976987970759411 -0.0006973787640831148 -1.5707968138185884
          name "ankle touch sensor"
          boundingObject Box {
            size 0.04 0.1 0.04
          }
          physics Physics {
            density -1
            mass 0.001
          }
          type "force-3d"
          lookupTable [
            0 0 0
            5000 5000 0
          ]
          linearVelocity 7.155102777187114e-14 8.010696328497602e-09 8.501334167556064e-17
          angularVelocity 3.788048508235869e-15 -8.955780581301475e-17 -3.5778350166055365e-12
        }
        DEF ANKLE HingeJoint {
          jointParameters HingeJointParameters {
            position 1.5994672368596956
            axis 0 0 1
            anchor -0.025 0.05 0
          }
          device [
            RotationalMotor {
              name "ankle_z motor"
              maxVelocity 1000
              maxTorque 1000
            }
          ]
          endPoint DEF SHANK Solid {
            translation -0.024982294810499843 0.048668687961106745 3.246802354975809e-10
            rotation 8.592404043269079e-10 -8.83059575331857e-10 1 1.600587585197099
            children [
              DEF SHANK Group {
                children [
                  Transform {
                    rotation 1 0 0 1.57
                    children [
                      Shape {
                        appearance PBRAppearance {
                          baseColor 0.5 0.5 0
                          transparency 0.2
                        }
                        geometry Cylinder {
                          height 0.1
                          radius 0.02
                        }
                      }
                    ]
                  }
                  Transform {
                    translation 0.16 0 0
                    children [
                      Shape {
                        appearance DEF METAL_APPEARANCE PBRAppearance {
                          baseColor 0.5 0.5 0.5
                          roughness 1.1102230246251565e-16
                          metalness 0
                        }
                        geometry Box {
                          size 0.32 0.02 0.1
                        }
                      }
                    ]
                  }
                  Transform {
                    translation 0.4 0 0
                    rotation 0 0 1 0
                    children [
                      Shape {
                        appearance DEF METAL_APPEARANCE PBRAppearance {
                          baseColor 0 0.5 0
                          roughness 1.11022e-16
                          metalness 0
                        }
                        geometry Sphere {
                          radius 0.1
                        }
                      }
                    ]
                  }
                ]
              }
            ]
            name "shank solid"
            boundingObject USE SHANK
            physics Physics {
              density -1
              mass 5
            }
          }
        }
        DEF FOOT Solid {
          children [
            DEF Foot Group {
              children [
                Transform {
                  translation 0 0.015 0
                  children [
                    Shape {
                      appearance DEF METAL_APPEARANCE PBRAppearance {
                        baseColor 0.5 0.5 0.5
                        roughness 1.1102230246251565e-16
                        metalness 0
                      }
                      geometry Box {
                        size 0.25 0.03 0.1
                      }
                    }
                  ]
                }
              ]
            }
          ]
        }
      ]
      name "foot touch sensor"
      boundingObject DEF Foot Group {
        children [
          Transform {
            translation 0 0.015 0
            children [
              Shape {
                appearance DEF METAL_APPEARANCE PBRAppearance {
                  baseColor 0.5 0.5 0.5
                  roughness 1.1102230246251565e-16
                  metalness 0
                }
                geometry Box {
                  size 0.25 0.03 0.1
                }
              }
            ]
          }
        ]
      }
      physics Physics {
        density -1
        mass 0.001
      }
      rotationStep 0.261799
      recognitionColors [
        0 0 0
      ]
      type "force-3d"
      lookupTable [
        0 0 0
        5000 5000 0
      ]
      linearVelocity 3.3274926697434327e-15 1.636524249448712e-12 3.83049217647839e-15
      angularVelocity 2.4445279593909303e-13 8.739579609392512e-15 -1.6810948113542355e-13
    }
  ]
  name "leg"
  boundingObject DEF Foot Group {
    children [
      Transform {
        translation 0 0.015 0
        children [
          Shape {
            appearance DEF METAL_APPEARANCE PBRAppearance {
              baseColor 0.5 0.5 0.5
              roughness 1.1102230246251565e-16
              metalness 0
            }
            geometry Box {
              size 0.25 0.03 0.1
            }
          }
        ]
      }
    ]
  }
  physics Physics {
    density -1
    mass 0.5
  }
  rotationStep 0.261799
  controller "ZMP_control"
  linearVelocity 3.3928725085805897e-15 -5.844489691922021e-11 3.863558866029581e-15
  angularVelocity 1.3986837175330838e-13 8.73956895655655e-15 -2.511365201241464e-13
}
