#VRML_SIM R2019b utf8
WorldInfo {
  info [
    "Example world for demonstrating the InertialUnit."
  ]
  title "Inertial Unit"
  basicTimeStep 16
}
Viewpoint {
  orientation 0.9774311464489607 0.21124557539988278 -0.0019133283677409511 5.955789585326972
  position -0.36286448318925446 0.8146035094504929 2.6704732670369866
}
TexturedBackground {
}
TexturedBackgroundLight {
}
CircleArena {
}
DEF ROBOT Robot {
  translation 8.65616986854131e-05 -0.010627062054533294 -2.1110323231176813e-11
  rotation 2.088515324898914e-11 3.8505159928562544e-10 1 0.0013923886249133138
  children [
    DEF YAW_HINGE_JOINT HingeJoint {
      endPoint Solid {
        rotation 1 0 0 0
        children [
          DEF PITCH_HINGE_JOINT HingeJoint {
            jointParameters HingeJointParameters {
              position 0.05000088477310244
              axis 0 0 1
              anchor -0.025 0.05 0
            }
            device [
              RotationalMotor {
                name "pitch motor"
                maxVelocity 1000
                minPosition -3.14
                maxPosition 3.14
                maxTorque 1000
              }
            ]
            endPoint Solid {
              translation -0.025 0.05 0
              rotation 5.556489573716784e-17 -5.897600317740932e-17 1 1.6207978847731024
              children [
                DEF PITCH_GROUP Group {
                  children [
                    Transform {
                      rotation 1 0 0 1.5708
                      children [
                        Shape {
                          appearance DEF PLASTIC_APPEARANCE PBRAppearance {
                            baseColor 1 0.666667 0
                            roughness 1
                            metalness 0
                          }
                          geometry Cylinder {
                            height 0.1
                            radius 0.03
                            subdivision 16
                          }
                        }
                      ]
                    }
                    Transform {
                      translation 0.2 0 0
                      children [
                        Shape {
                          appearance DEF METAL_APPEARANCE PBRAppearance {
                            baseColor 0.5 0.5 0.5
                            roughness 1.1102230246251565e-16
                            metalness 0
                          }
                          geometry Box {
                            size 0.4 0.02 0.05
                          }
                        }
                      ]
                    }
                    Transform {
                      translation 0.4 0 0
                      rotation 0 0 1 1.5708
                      children [
                        Shape {
                          appearance DEF METAL_APPEARANCE PBRAppearance {
                            baseColor 0 0.5 0
                            transparency 0.3
                            roughness 1.11022e-16
                            metalness 0
                          }
                          geometry Sphere {
                            radius 0.1
                          }
                        }
                      ]
                    }
                  ]
                }
              ]
              boundingObject USE PITCH_GROUP
              physics Physics {
              }
              linearVelocity 4.83424237117629e-11 -2.515325821069282e-13 2.435340948794768e-14
              angularVelocity 5.881796190723055e-14 1.7601100509169548e-16 5.759860291710877e-12
            }
          }
          DEF YAW_GROUP Group {
            children [
              Transform {
                translation 0 0.025 0
                children [
                  Shape {
                    appearance DEF METAL_APPEARANCE PBRAppearance {
                      baseColor 0.5 0.5 0.5
                      roughness 1.1102230246251565e-16
                      metalness 0
                    }
                    geometry Box {
                      size 0.25 0.03 0.1
                    }
                  }
                ]
              }
              Transform {
                translation -0.025 0.05 0
                rotation 1 0 0 1.5708
                children [
                  Shape {
                    appearance DEF METAL_APPEARANCE PBRAppearance {
                      baseColor 0.5 0.5 0.5
                      roughness 1.1102230246251565e-16
                      metalness 0
                    }
                    geometry Cylinder {
                      height 0.1
                      radius 0.025
                    }
                  }
                ]
              }
            ]
          }
        ]
        boundingObject USE YAW_GROUP
        physics Physics {
        }
        linearVelocity 5.053423506694157e-11 -2.9903555940171585e-14 2.1232208562218655e-15
        angularVelocity 6.564392666211186e-14 2.548262553027047e-17 5.757678211444817e-12
      }
    }
  ]
  boundingObject USE YAW_GROUP
  physics Physics {
  }
  controller "ZMP_control"
  linearVelocity -5.078454583974483e-11 -3.514772433588037e-14 -1.8428145573268983e-15
  angularVelocity -5.319113134891351e-14 8.108504315313223e-17 6.7755290395773e-12
}
