#VRML_SIM R2019b utf8
WorldInfo {
  info [
    "Aldebaran's Nao H25 V5.0"
    "NAO is a programmable, 57-cm tall humanoid robot."
    "The body has 25 degrees of freedom (DOF)."
    "The sensors include 2 cameras, 4 microphones, sonar rangefinder, 2 IR emitters and receivers, 1 inertial board, and 8 pressure sensors."
  ]
  title "Aldebaran's Nao"
  basicTimeStep 4
  FPS 20
  contactProperties [
    ContactProperties {
      material1 "NAO foot material"
      coulombFriction [
        7
      ]
      bounce 0.3
      bounceVelocity 0.003
    }
  ]
}
Viewpoint {
  orientation -0.19201123631802516 0.9640054199966014 0.1839163813932833 1.5003987975383115
  position 1.2969465246954563 0.7717997454646747 6.089156641279435
  follow "NAO"
}
TexturedBackground {
}
TexturedBackgroundLight {
}
DEF Nao Nao {
  hidden position_0_0 1.234776446994743e-06
  hidden position2_0_0 -1.8566328700344103e-08
  hidden position_0_1 3.407400655586809e-08
  hidden position_0_2 -3.3059088320693854e-08
  translation -0.005622232982088406 0.33376146361819015 5.923072585299928
  rotation 0.9999996432196487 0.0007856666411268724 0.0003103038905903106 -1.571723020672679
  controller "<extern>"
  supervisor TRUE
  headSlot [
    DEF RobotHead Connector {
      translation 0 0.073 -0.01
      rotation 0.9999999999999999 0 0 0
      name "robot_head_connector"
      model "boom_head"
      rotationStep 0.261799
      isLocked TRUE
      autoLock TRUE
      distanceTolerance 0.1
      axisTolerance 0.5
      rotationTolerance 0.5
    }
  ]
}
DEF BoomBase Robot {
  translation 0 0.25 0.85
  children [
    DEF BoomBase Group {
      children [
        DEF BoomBaseJoint Transform {
          translation 0 0.25 0
          children [
            DEF BoomBaseJoint BallJoint {
              jointParameters BallJointParameters {
                position 0.002946906189375309
              }
              jointParameters2 JointParameters {
                position -0.0013765973048914775
              }
              jointParameters3 JointParameters {
                position -0.07799790800494931
              }
              device [
                PositionSensor {
                }
              ]
              device2 [
                PositionSensor {
                }
              ]
              device3 [
                PositionSensor {
                }
              ]
              endPoint DEF BoomBody Solid {
                translation -0.003621599976910721 0.0011167026056707846 2.499887180824359
                rotation 0.8969442368808404 -0.31323773420481504 -0.3120467237393789 1.6786112833344602
                children [
                  DEF BoomBody Group {
                    children [
                      DEF BoomBody Connector {
                        translation 0 2.5 0
                        rotation 0 1 0 0.523799
                        name "boom_body_connector"
                        model "boom_head"
                        isLocked TRUE
                        autoLock TRUE
                        distanceTolerance 0.1
                        axisTolerance 0.5
                        rotationTolerance 0.5
                      }
                      DEF BoomBody Shape {
                        appearance PBRAppearance {
                        }
                        geometry Cylinder {
                          height 5
                          radius 0.01
                        }
                      }
                    ]
                  }
                ]
                name "boom_body_solid"
                boundingObject USE BoomBody
                physics Physics {
                  density 0.1
                }
              }
            }
            DEF BoomBaseJoint Shape {
              appearance PBRAppearance {
              }
              geometry DEF BoomBaseJoint Sphere {
                radius 0.1
              }
            }
          ]
        }
        DEF BoomBase Shape {
          appearance PBRAppearance {
          }
          geometry Cylinder {
            height 0.5
            radius 0.1
          }
        }
      ]
    }
  ]
  name "boom_base_solid"
  supervisor TRUE
}
Floor {
  size 20 20
  appearance Appearance {
    texture ImageTexture {
      url [
        "textures/sand.jpg"
      ]
    }
  }
}
