#VRML_SIM R2019b utf8
WorldInfo {
  info [
    "Aldebaran's Nao H25 V5.0"
    "NAO is a programmable, 57-cm tall humanoid robot."
    "The body has 25 degrees of freedom (DOF)."
    "The sensors include 2 cameras, 4 microphones, sonar rangefinder, 2 IR emitters and receivers, 1 inertial board, and 8 pressure sensors."
  ]
  title "Aldebaran's Nao"
  basicTimeStep 4
  FPS 20
  contactProperties [
    ContactProperties {
      material1 "NAO foot material"
      coulombFriction [
        7
      ]
      bounce 0.3
      bounceVelocity 0.003
    }
  ]
}
Viewpoint {
  orientation -0.3144199926158374 0.945378586054132 0.0860197493239019 0.35431401858835765
  position 1.5437918045201517 0.7803162147883025 8.754106269536372
  follow "NAO"
}
TexturedBackground {
}
TexturedBackgroundLight {
}
DEF Nao Nao {
  hidden rotation_11 -9.28211512716202e-09 0.015034486849424586 -0.9998869757153427 1.234909853643238e-06
  hidden rotation_19 0 -0.7071067811865476 -0.7071067811865476 2.9802322387695313e-08
  hidden rotation_29 0 0.7071067811865476 -0.7071067811865476 2.9802322387695313e-08
  translation -0.005622232982088406 0.33376146361819015 5.923072585299928
  rotation 0.9999996432196487 0.0007856666411268724 0.0003103038905903106 -1.571723020672679
  controller "rl"
  supervisor TRUE
  headSlot [
    DEF RobotHead Connector {
      translation 0 0.073 -0.01
      rotation 0.9999999999999999 0 0 0
      name "robot_head_connector"
      model "boom_head"
      rotationStep 0.261799
      isLocked TRUE
      autoLock TRUE
      distanceTolerance 0.1
      axisTolerance 0.5
      rotationTolerance 0.5
    }
  ]
}
DEF BoomBase Robot {
  translation 0 0.25 0.85
  children [
    DEF BoomBase Group {
      children [
        DEF BoomBaseJoint Transform {
          translation 0 0.25 0
          children [
            DEF BoomBaseJoint BallJoint {
              jointParameters BallJointParameters {
                position 0.002946906189375309
              }
              jointParameters2 JointParameters {
                position -0.0013765973048914775
              }
              jointParameters3 JointParameters {
                position -0.07799790800494931
              }
              device [
                PositionSensor {
                }
              ]
              device2 [
                PositionSensor {
                }
              ]
              device3 [
                PositionSensor {
                }
              ]
              endPoint DEF BoomBody Solid {
                translation -0.0034045105008786935 0.001665028333596265 2.4998871808243583
                rotation 0.849805129606559 -0.3732683245700377 -0.3721585677732764 1.731977838253094
                children [
                  DEF BoomBody Group {
                    children [
                      DEF BoomBody Connector {
                        translation 0 2.5 0
                        rotation 0 1 0 0.523799
                        name "boom_body_connector"
                        model "boom_head"
                        isLocked TRUE
                        autoLock TRUE
                        distanceTolerance 0.1
                        axisTolerance 0.5
                        rotationTolerance 0.5
                      }
                      DEF BoomBody Shape {
                        appearance PBRAppearance {
                        }
                        geometry Cylinder {
                          height 5
                          radius 0.01
                        }
                      }
                    ]
                  }
                ]
                name "boom_body_solid"
                boundingObject USE BoomBody
                physics Physics {
                  density 0.1
                }
              }
            }
            DEF BoomBaseJoint Shape {
              appearance PBRAppearance {
              }
              geometry DEF BoomBaseJoint Sphere {
                radius 0.1
              }
            }
          ]
        }
        DEF BoomBase Shape {
          appearance PBRAppearance {
          }
          geometry Cylinder {
            height 0.5
            radius 0.1
          }
        }
      ]
    }
  ]
  name "boom_base_solid"
  supervisor TRUE
}
Floor {
  size 20 20
  appearance Appearance {
    texture ImageTexture {
      url [
        "textures/sand.jpg"
      ]
    }
  }
}
