#VRML_SIM R2019b utf8
WorldInfo {
  info [
    "Aldebaran's Nao H25 V5.0"
    "NAO is a programmable, 57-cm tall humanoid robot."
    "The body has 25 degrees of freedom (DOF)."
    "The sensors include 2 cameras, 4 microphones, sonar rangefinder, 2 IR emitters and receivers, 1 inertial board, and 8 pressure sensors."
  ]
  title "Aldebaran's Nao"
  basicTimeStep 4
  FPS 20
  contactProperties [
    ContactProperties {
      material1 "NAO foot material"
      coulombFriction [
        7
      ]
      bounce 0.3
      bounceVelocity 0.003
    }
  ]
}
Viewpoint {
  orientation -0.5234509798218244 0.8440969013236412 0.11618731815219242 0.38345960247116107
  position 1.1741374011172125 0.8238926434018751 8.436426677703173
  follow "NAO"
}
TexturedBackground {
}
TexturedBackgroundLight {
}
Nao {
  hidden position_0_0 1.234776446994743e-06
  hidden position2_0_0 -1.8566328700344103e-08
  hidden position_0_1 1.5699999766346002
  hidden position2_0_1 3.407400655586809e-08
  hidden position_0_2 1.5699999766347228
  hidden position2_0_2 -3.3059088320693854e-08
  hidden position_0_3 6.756130942374333e-07
  hidden position_0_4 2.966842961797309e-06
  hidden rotation_11 9.282115127162018e-09 -0.015034486849424582 0.9998869757153427 1.234909853643238e-06
  hidden rotation_19 1.7037003277934042e-08 0.9999999999999997 1.7050576103303518e-08 1.5699999766346007
  hidden position_19_0 1.1582448735738406e-09
  hidden position_20_0 1.1743739431317874e-09
  hidden position_21_0 1.0705909209566611e-09
  hidden position_22_0 1.5574131146047375e-10
  hidden position_22_1 1.5573853587707825e-10
  hidden position_22_2 1.5981889013541775e-11
  hidden rotation_23 0 1 0 0.959999999844259
  hidden position_23_0 6.580669498254553e-11
  hidden rotation_24 0 1 0 0.9599999999341935
  hidden position_24_0 5.038526510451977e-12
  hidden rotation_26 0 1 0 0.9599999998442614
  hidden position_26_0 6.580292023383385e-11
  hidden rotation_27 0 1 0 0.9599999999341974
  hidden position_27_0 5.039636697713358e-12
  hidden position_29_0 1.5899171351726923e-11
  hidden rotation_31 -1.652954416034693e-08 0.9999999999999999 -1.6542712709570692e-08 1.5699999766347228
  hidden position_31_0 -1.1523111353994864e-09
  hidden position_32_0 1.1724247192448642e-09
  hidden position_33_0 1.0769427806373017e-09
  hidden position_34_0 1.5573831380221555e-10
  hidden position_34_1 1.5574009017867113e-10
  hidden position_34_2 1.5981778139653954e-11
  hidden rotation_35 0 1 0 0.9599999998442619
  hidden position_35_0 6.580447456111e-11
  hidden rotation_36 0 1 0 0.9599999999341959
  hidden position_36_0 5.039081733722461e-12
  hidden rotation_38 0 0.9999999999999999 0 0.95999999984426
  hidden position_38_0 6.580558476428252e-11
  hidden rotation_39 0 1 0 0.9599999999341945
  hidden position_39_0 5.039414762621128e-12
  hidden position_41_0 1.5898727265625595e-11
  hidden rotation_43 0 0.7071067811865475 0.7071067811865475 6.756653814765625e-07
  hidden position_43_0 -3.858832484660013e-06
  hidden rotation_44 -1 0 0 3.858796600791135e-06
  hidden position_44_0 -6.730709950207797e-07
  hidden rotation_45 0 -1 0 6.730311984203021e-07
  hidden position_45_0 3.8268244626029673e-07
  hidden rotation_46 0 0.9999999999999999 0 3.8281776245430556e-07
  hidden position_46_0 2.382380947361862e-07
  hidden rotation_47 0 1 0 2.3841857910156266e-07
  hidden position_47_0 -5.06174300696216e-07
  hidden rotation_48 -1 0 0 5.057621821307297e-07
  hidden translation_49 0.01999995153242605 -0.0070029230134691645 -0.04099742521543354
  hidden rotation_49 4.7529972765227253e-08 -2.720332353841457e-08 0.9999999999999986 -3.1415852346842668
  hidden rotation_53 0 0.7071067811865476 -0.7071067811865476 2.966790882288446e-06
  hidden position_53_0 -0.001308586229636255
  hidden rotation_54 -1 0 0 0.0013085862295453797
  hidden position_54_0 -2.9729186121876425e-06
  hidden rotation_55 0 -1 0 2.972921703381637e-06
  hidden position_55_0 1.7014172729875755e-06
  hidden rotation_56 0 0.9999999999999999 0 1.7013446064224856e-06
  hidden position_56_0 4.4712578923296416e-07
  hidden rotation_57 0 1 0 4.4703483581543064e-07
  hidden position_57_0 -1.8234680787543311e-06
  hidden rotation_58 -1 0 0 1.8235514808629614e-06
  hidden translation_59 0.020000101400825223 0.006987239628663211 -0.040993962732740905
  hidden rotation_59 5.1196166076394164e-08 -5.698464222752711e-08 0.9999999999999971 -3.141585305507066
  translation -0.005622232982088406 0.33376146361819015 5.923072585299928
  rotation 0.9999996432196487 0.0007856666411268724 0.0003103038905903106 -1.571723020672679
  controller "rl"
  supervisor TRUE
  headSlot [
    DEF RobotHead Connector {
      translation 0 0.073 -0.01
      rotation 0.9999999999999999 0 0 0
      name "robot_head_connector"
      model "boom_head"
      rotationStep 0.261799
      isLocked TRUE
      autoLock TRUE
      distanceTolerance 0.1
      axisTolerance 0.5
      rotationTolerance 0.5
    }
  ]
}
DEF BoomBase Robot {
  translation 0 0.25 0.85
  children [
    DEF BoomBase Group {
      children [
        DEF BoomBaseJoint Transform {
          translation 0 0.25 0
          children [
            DEF BoomBaseJoint BallJoint {
              jointParameters BallJointParameters {
                position 0.002946906189375309
              }
              jointParameters2 JointParameters {
                position -0.0013765973048914775
              }
              jointParameters3 JointParameters {
                position -0.07799790800494931
              }
              device [
                PositionSensor {
                }
              ]
              device2 [
                PositionSensor {
                }
              ]
              device3 [
                PositionSensor {
                }
              ]
              endPoint DEF BoomBody Solid {
                translation -0.0037511192715710294 0.0005404769307936208 2.4998871808243597
                rotation 0.9371845609401622 -0.24729399481687303 -0.24603003650552036 1.6350105854892663
                children [
                  DEF BoomBody Group {
                    children [
                      DEF BoomBody Connector {
                        translation 0 2.5 0
                        rotation 0 1 0 0.523799
                        name "boom_body_connector"
                        model "boom_head"
                        isLocked TRUE
                        autoLock TRUE
                        distanceTolerance 0.1
                        axisTolerance 0.5
                        rotationTolerance 0.5
                      }
                      DEF BoomBody Shape {
                        appearance PBRAppearance {
                        }
                        geometry Cylinder {
                          height 5
                          radius 0.01
                        }
                      }
                    ]
                  }
                ]
                name "boom_body_solid"
                boundingObject USE BoomBody
                physics Physics {
                  density 0.1
                }
                linearVelocity 2.313136688162331e-06 -3.5959797235766433e-06 -4.431861362167286e-06
                angularVelocity 1.6233859186630362e-06 9.584317699102395e-07 -9.07393947231864e-06
              }
            }
            DEF BoomBaseJoint Shape {
              appearance PBRAppearance {
              }
              geometry DEF BoomBaseJoint Sphere {
                radius 0.1
              }
            }
          ]
        }
        DEF BoomBase Shape {
          appearance PBRAppearance {
          }
          geometry Cylinder {
            height 0.5
            radius 0.1
          }
        }
      ]
    }
  ]
  name "boom_base_solid"
  supervisor TRUE
}
Floor {
  size 20 20
  appearance Appearance {
    texture ImageTexture {
      url [
        "textures/sand.jpg"
      ]
    }
  }
}
