#VRML_SIM R2019b utf8
WorldInfo {
  info [
    "Benchmark objective:"
    "keep the pendulum in equilibrium as long as possible."
    "Perturbations with increasing strength are applied to the pendulum."
    "measure the simulation time "
  ]
  title "Inverted Pendulum"
  window "inverted_pendulum"
  physics "inverted_pendulum_perturbation"
  basicTimeStep 4
  lineScale 0.01
}
Viewpoint {
  orientation -0.0036081974447530482 -0.9961978908393254 -0.08704448976517153 3.128970911307828
  position -0.03756414000239472 0.24584341182952416 -1.7944487239199343
  follow "e-puck"
}
TexturedBackground {
}
TexturedBackgroundLight {
}
Floor {
  size 40 5
  appearance PBRAppearance {
    baseColorMap ImageTexture {
      url [
        "textures/interlaced_parquetry.jpg"
      ]
    }
    roughness 1
    metalness 0
  }
}
Wall {
  translation 0 0 2.52
  size 40 2.4 0.2
}
E-puck {
  hidden position_0_0 6.614591547982001
  hidden position_0_1 6.61459154602916
  hidden rotation_1 1 0 0 5.951779066377172
  hidden rotation_2 1 0 0 5.951779068330013
  translation -0.1275079045787615 -2.2096471618479607e-06 -0.9799991790296436
  rotation -0.0022701548278313993 0.9999948340783582 0.002275568863951027 1.5708216835916058
  controller "inverted_pendulum"
  window ""
  turretSlot [
    Transform {
      translation 0 0 -0.01
      rotation 0 0 1 1.5707997
      children [
        Shape {
          appearance PBRAppearance {
            baseColor 0.8 0.8 0.8
            metalness 0.2
            textureTransform TextureTransform {
              rotation 1.5708
            }
          }
          geometry DEF JOINT_GEOM Cylinder {
            height 0.01
            radius 0.004
          }
        }
      ]
    }
    HingeJoint {
      jointParameters DEF PENDULUM_PARAMETERS HingeJointParameters {
        position -1.6002168423536258
        anchor 0 0 -0.01
        minStop -1.6
        maxStop 1.6
      }
      device [
        PositionSensor {
          name "pendulum sensor"
          resolution 1e-05
        }
      ]
      endPoint DEF PENDULUM Solid {
        translation 0 -0.002353301175459543 -0.08996537998507198
        rotation -1 0 0 3.171016842353626
        children [
          DEF POLE Transform {
            translation 0 0 -0.04
            rotation 1 0 0 1.5707997
            children [
              Shape {
                appearance PBRAppearance {
                  baseColor 0.8 0.8 0.8
                  baseColorMap ImageTexture {
                    url [
                      "textures/wood.jpg"
                    ]
                  }
                  roughness 1
                  metalness 0
                  textureTransform TextureTransform {
                  }
                }
                geometry Cylinder {
                  height 0.075
                  radius 0.0015
                }
              }
            ]
          }
          DEF BALL Transform {
            rotation 1 0 0 4.712389
            children [
              Shape {
                appearance PBRAppearance {
                  baseColor 0.8 0.8 0.8
                  baseColorMap ImageTexture {
                    url [
                      "textures/red_rubber.jpg"
                    ]
                  }
                  roughness 1
                  metalness 0
                  textureTransform TextureTransform {
                  }
                }
                geometry Sphere {
                  radius 0.0075
                  subdivision 3
                }
              }
            ]
          }
        ]
        boundingObject USE BALL
        physics Physics {
          density -1
          mass 0.05
        }
        linearVelocity -1.7062348453780348e-14 1.9166126890952295e-15 -1.0606611979344415e-14
        angularVelocity -2.0796847362183813e-15 -1.160133265049607e-13 -1.680005437140958e-14
      }
    }
  ]
}
PottedTree {
  translation 2.3590843 2.3314684e-15 1.5713239
  rotation 0 -1 0 3.1415927
}
PottedTree {
  translation -8.1991063 2.3314684e-15 1.7283871
  rotation 0 -1 0 4.712389
  name "potted tree(1)"
}
PottedTree {
  translation 6.9386009 2.3314684e-15 1.6952438
  rotation 0 -1 0 4.712389
  name "potted tree(2)"
}
LandscapePainting {
  translation 4.93 1.41 2.4
  rotation 0 -1 0 3.1415927
}
DEF PAINTING PortraitPainting {
  translation -4.09 1.515 2.4
  rotation 0 -1 0 3.1415927
}
Chair {
  translation -6.7892764 0 1.6094394
  rotation 0 1 0 1.5707963
}
Chair {
  translation -5.8129552 0 1.6194171
  rotation 0 1 0 1.5707963
  name "chair(1)"
}
Sofa {
  translation 0.46911152 -4.5519144e-14 1.5328805
  rotation 0 1 0 1.5707963
}
InvertedPendulumBenchmark {
}
